<?xml version="1.0"?> 
<robot xmlns:xacro="http://www.ros.org/wiki/xacro" name="bumperbot">

    <xacro:arg name="is_ignition" default="false"/>
    
    <xacro:include filename="$(find bumperbot_description)/urdf/bumperbot_gazebo.xacro"/>
    <xacro:include filename="$(find bumperbot_description)/urdf/bumperbot_ros2_control.xacro"/>

    <link name="base_footprint"/>

    <link name="base_link">
        <inertial>
            <origin rpy="0 0 0" xyz="0 0 0"/>
            <mass value="0.8"/>
            <inertia ixx="0.001" ixy="0" ixz="0" iyy="0.001" iyz="0" izz="0.001"/>
        </inertial>
        <visual>
            <origin rpy="0 0 0" xyz="0 0 0"/>
            <geometry>
                <mesh filename="package://bumperbot_description/meshes/base_link.STL"/>
            </geometry>
            <material name="Purple">
                <color rgba="0.5 0 0.5 1"/>
            </material>
        </visual>
        <collision>
            <origin rpy="0 0 0" xyz="0 0 0.02"/>
            <geometry>
                <box size="0.16 0.14 0.05"/>
            </geometry>
        </collision>
    </link>

    <joint name="base_joint" type="fixed">
        <parent link="base_footprint"/>
        <child link="base_link"/>
        <origin rpy="0 0 0" xyz="0 0 0.033"/>
    </joint>
    
    <link name="wheel_right_link">
        <inertial>
            <origin rpy="0 0 0" xyz="0 -0.014 0"/>
            <mass value="0.05"/>
            <inertia ixx="0.00001" ixy="0" ixz="0" iyy="0.00001" iyz="0" izz="0.00001"/>
        </inertial>
        <visual>
            <origin rpy="1.57 0 0" xyz="0 0 0"/>
            <geometry>
                <mesh filename="package://bumperbot_description/meshes/wheel_right_link.STL"/>
            </geometry>
            <material name="light_blue"><color rgba="0 0 1 1"/></material>
        </visual>
        <collision>
            <origin xyz="0.0 0.0 0.0" rpy="1.57 0.0 0.0"/>
            <geometry><sphere radius="0.033"/></geometry>
        </collision>
    </link>

    <joint name="wheel_right_joint" type="continuous"> 
        <parent link="base_link"/> 
        <child link= "wheel_right_link"/>    
        <axis xyz="0 1 0"/>
        <origin rpy="0 0 0" xyz="0 -0.07 0"/>
    </joint>

    <link name="wheel_left_link">
        <inertial>
            <origin xyz="0 0.014 0" rpy="0 0 0" />
            <mass value="0.05" />
            <inertia ixx="0.00001" ixy="0" ixz="0" iyy="0.00001" iyz="0" izz="0.00001" />
        </inertial>
        <visual>
            <origin rpy="-1.57 0 0" xyz="0 0 0"/>
            <geometry>
                <mesh filename="package://bumperbot_description/meshes/wheel_left_link.STL"/>
            </geometry>
            <material name="light_blue"><color rgba="0 0 1 1"/></material>
        </visual>
        <collision>
            <origin xyz="0.0 0.0 0.0" rpy="1.57 0.0 0.0"/>
            <geometry><sphere radius="0.033"/></geometry>
        </collision>
    </link>
    
    <joint name="wheel_left_joint" type="continuous">
        <parent link="base_link"/>
        <child link="wheel_left_link"/>
        <axis xyz="0 1 0"/>
        <origin rpy="0 0 0" xyz="0 0.07 0"/>
    </joint>

    <joint name="laser_joint" type="fixed">
        <parent link="base_link"/>
        <child link="laser_frame"/>
        <origin rpy="0 0 0" xyz="0 0 0.55"/> 
    </joint>

    <link name="laser_frame">
        <inertial>
            <origin xyz="0 0 0" rpy="0 0 0" />
            <mass value="0.1" />
            <inertia ixx="0.0001" ixy="0" ixz="0" iyy="0.0001" iyz="0" izz="0.0001" />
        </inertial>
        
        <visual>
            <geometry>
                <mesh filename="package://bumperbot_description/meshes/VLP16_base_1.stl" scale="0.8 0.8 1.0"/>
            </geometry>
            <material name="grey"><color rgba="0.5 0.5 0.5 1"/></material>
        </visual>

        <visual>
            <geometry>
                <mesh filename="package://bumperbot_description/meshes/VLP16_base_2.stl" scale="0.8 0.8 1.0"/>
            </geometry>
            <material name="grey"/>
        </visual>

        <visual>
            <geometry>
                <mesh filename="package://bumperbot_description/meshes/VLP16_scan.stl" scale="0.8 0.8 1.0"/>
            </geometry>
            <material name="blue"><color rgba="0 0 0.8 1"/></material>
        </visual>

        </link>

</robot>